Traceback (most recent call last):
  File "/apps/Arch/software/GPAW/22.8.0-foss-2022a/bin/gpaw", line 8, in <module>
    sys.exit(main())
  File "/apps/Arch/software/GPAW/22.8.0-foss-2022a/lib/python3.10/site-packages/gpaw/cli/main.py", line 76, in main
    ase_main('gpaw', 'GPAW command-line tool', __version__,
  File "/apps/Arch/software/ASE/3.22.1-foss-2022a/lib/python3.10/site-packages/ase/cli/main.py", line 103, in main
    f(args)
  File "/apps/Arch/software/GPAW/22.8.0-foss-2022a/lib/python3.10/site-packages/gpaw/cli/python.py", line 36, in run
    runpy.run_path(args.arguments[0], run_name='__main__')
  File "/apps/Arch/software/Python/3.10.4-GCCcore-11.3.0/lib/python3.10/runpy.py", line 269, in run_path
    return _run_module_code(code, init_globals, run_name,
  File "/apps/Arch/software/Python/3.10.4-GCCcore-11.3.0/lib/python3.10/runpy.py", line 96, in _run_module_code
    _run_code(code, mod_globals, init_globals,
  File "/apps/Arch/software/Python/3.10.4-GCCcore-11.3.0/lib/python3.10/runpy.py", line 86, in _run_code
    exec(code, run_globals)
  File "Task5.py", line 4, in <module>
    atoms7 = db7.get("id =74").toatoms() #for 6 atoms
  File "/apps/Arch/software/ASE/3.22.1-foss-2022a/lib/python3.10/site-packages/ase/db/core.py", line 432, in get
    raise KeyError('no match')
KeyError: 'no match'
srun: error: vera35-1: task 0: Exited with exit code 1
